<?xml version="1.0"?>
<robot name="hermesArm">

 <!-- **************************** BASE ***************************** -->
  <link name="base" />
  <link name="link1" />
  <link name="link2" />
  <link name="link3" />
  <link name="link4" />
  <link name="link5" />
  <link name="link6" />
  <link name="link7" />

  <joint name="joint1" type="revolute">
    <parent link="base"/>
    <child link="link1"/>
    <limit effort="100" velocity="100" lower="-3.14" upper="3.14" />
  </joint>

  <joint name="joint2" type="revolute">
    <parent link="link1"/>
    <child link="link2"/>
    <limit effort="100" velocity="100" lower="-1.83" upper="1.83" />
  </joint>

  <joint name="joint3" type="revolute">
    <parent link="link2"/>
    <child link="link3"/>
    <limit effort="100" velocity="100" lower="-3.14" upper="3.14" />
  </joint>

  <joint name="joint4" type="revolute">
    <parent link="link3"/>
    <child link="link4"/>
    <limit effort="100" velocity="100" lower="-1.83" upper="1.83" />
  </joint>

  <joint name="joint5" type="revolute">
    <parent link="link4"/>
    <child link="link5"/>
    <limit effort="100" velocity="100" lower="-3.14" upper="3.14" />
  </joint>

  <joint name="joint6" type="revolute">
    <parent link="link5"/>
    <child link="link6"/>
    <limit effort="100" velocity="100" lower="-1.83" upper="1.83" />
  </joint>

  <joint name="joint7" type="revolute">
    <parent link="link6"/>
    <child link="link7"/>
    <limit effort="100" velocity="100" lower="-3.14" upper="3.14" />
  </joint>

</robot>


